<?xml version="1.0"?>
<robot xmlns:xacro="http://www.ros.org/wiki/xacro">
    <xacro:property name="pi" value="3.1415926535897931"/>
    <xacro:macro name="cylinder_inertia" params="mass r l">
        <inertia ixx="${mass*(3*r*r+l*l)/12}" ixy="0" ixz="0"
                 iyy="${mass*(3*r*r+l*l)/12}" iyz="0"
                 izz="${mass*(r*r)/2}"/>
    </xacro:macro>
    <xacro:macro name="link_wheel" params="name">
        <xacro:property name="mass" value="0.5"/>
        <xacro:property name="width" value="0.025"/>
        <xacro:property name="radius" value="0.038"/>
        <link name="${name}">
            <inertial>
                <mass value="${mass}"/>
                <origin rpy="0 1.5707 1.5707" xyz="0 0 0"/>
                <!--              <inertia ixx="0.000526666666667" ixy="0" ixz="0" iyy="0.000526666666667" iyz="0" izz="0.001"/>-->

                <!--                <inertia ixx="${1/12*10*3*0.17^2+1/12*5*3*0.08^2}" ixy="0.0" ixz="0.0" iyy="${1/12*10*3*0.17^2+1/12*5*3*0.08^2}" iyz="0.0" izz="${1/2*10*0.17^2}"/>-->
                <xacro:cylinder_inertia mass="${mass}" r="${radius}" l="${width}" />
            </inertial>
            <collision name="link_${name}_wheel_collision">
                <origin rpy="0 1.5707 1.5707" xyz="0 0 0"/>
                <geometry>
                    <cylinder length="${width}" radius="${radius}"/>
                </geometry>
            </collision>
            <visual name="${name}_visual">
                <origin rpy="0 1.5707 1.5707" xyz="0 0 0"/>
                <geometry>
                    <cylinder length="${width}" radius="${radius}"/>
                </geometry>
            </visual>
        </link>
        <gazebo reference="${name}">
            <gravity>true</gravity>
            <material>Gazebo/Grey</material>
            <mu1>50</mu1>
            <mu2>10</mu2>
            <kp>10000000</kp>
            <kd>1</kd>
            <fdir1>1 0 0</fdir1>
            <minDepth>0.0001</minDepth>
            <maxContacts>1</maxContacts>
        </gazebo>
    </xacro:macro>

    <xacro:macro name="joint_wheel" params="name child origin_xyz parent">
        <joint name="${name}" type="continuous">
            <origin rpy="0 0 0" xyz="${origin_xyz}"/>
            <child link="${child}"/>
            <parent link="${parent}"/>
            <axis rpy="0 0 0" xyz="0 1 0"/>
            <limit effort="100" velocity="100"/>
            <joint_properties damping="0" friction="0"/>
        </joint>
    </xacro:macro>


</robot>